在Typescript编程当中，我们如何优雅的实现异步编程呢？async/await ！
 TypeScript 编译器默认使用 ES5 标准，而 ES5 标准中不包含 Promise 对象。async/await 是 ES2017（也称为 ES8）的特性。
在线运行界面 https://www.typescriptlang.org/zh/play

```typescript
async function asyncOperation(): Promise<string> {
    return Promise.resolve("Hello, async world!");
}
 
async function run() {
    const result = await asyncOperation();
    console.log(result);  // "Hello, async world!"
}
 
run();
```
在上述代码中，asyncOperation 是一个异步函数，返回一个 Promise。在 run 函数中，我们使用 await 关键字来等待 asyncOperation 的结果。

```typescript
async function asyncOperation(): Promise<number> {
    return new Promise((resolve, reject) => {
        setTimeout(() => resolve(10), 100);
    });
}
 
async function run() {
    const result = await asyncOperation();
    console.log(result);  // 10
}
 
run();
```
在这个例子中，asyncOperation 返回一个 Promise，该 Promise 将在100毫秒后解决，并返回数字10。

```typescript
async function asyncOperation1(): Promise<number> {
    return new Promise((resolve) => {
        setTimeout(() => resolve(10), 1000);
    });
}
 
async function asyncOperation2(): Promise<number> {
    return new Promise((resolve) => {
        setTimeout(() => resolve(20), 1000);
    });
}
 
async function run() {
    const result1 = await asyncOperation1();
    const result2 = await asyncOperation2();
    console.log(result1 + result2);  // 30
}
 
run();
```
在这个例子中，我们创建了两个异步函数，每一个都返回一个 Promise，并在100毫秒后解决。然后我们在 run 函数中使用 await 关键字来等待每一个 Promise 的结果，并将它们相加。
注意：在使用 await 关键字时，函数必须用 async 关键字标记为异步函数。否则，会出现语法错误。

```typescript
async function asyncOperation(): Promise<number> {
    throw new Error("Something went wrong");
}
 
async function run() {
    try {
        const result = await asyncOperation();
    } catch (error) {
        console.error(error);  // Error: Something went wrong
    }
}
 
run();
```
在这个例子中，asyncOperation 函数抛出一个错误。我们在 run 函数中使用 try...catch 块来捕获并处理这个错误。

```typescript
async function asyncOperation1(): Promise<number> {
    return new Promise((resolve) => {
        setTimeout(() => resolve(10), 100);
    });
}
 
async function asyncOperation2(): Promise<number> {
    return new Promise((resolve) => {
        setTimeout(() => resolve(20), 100);
    });
}
 
async function run() {
    const [result1, result2] = await Promise.all([asyncOperation1(), asyncOperation2()]);
    console.log(result1 + result2);  // 30
}
 
run();
```
在这个例子中，我们使用 Promise.all 来并行执行多个异步操作，并等待所有的 Promise 都完成。然后我们将结果打印出来。
注意：Promise.all 返回的 Promise 将在所有给定的 Promise 都解决之后解决。如果任何一个给定的 Promise 拒绝，Promise.all 返回的 Promise会立即被拒绝，并且拒绝的原因会是那个首先被拒绝的Promise的拒绝原因。这意味着，即使其他的Promise还未完成，Promise.all也会停止等待，直接返回一个拒绝的Promise。

以下是一个例子，展示了如果asyncOperation1被拒绝，Promise.all会如何处理：
```typescript
async function asyncOperation1(): Promise<number> {  
    return new Promise((resolve, reject) => {  
        setTimeout(() => reject('Operation 1 failed'), 100);  
    });  
}  
  
async function asyncOperation2(): Promise<number> {  
    return new Promise((resolve) => {  
        setTimeout(() => resolve(20), 100);  
    });  
}  
  
async function run() {  
    try {  
        const [result1, result2] = await Promise.all([asyncOperation1(), asyncOperation2()]);  
        console.log(result1 + result2);  
    } catch (error) {  
        console.error(error);  // 'Operation 1 failed'  
    }  
}  
  
run();
```

在这个例子中，asyncOperation1会在100毫秒后被拒绝，并返回拒绝原因'Operation 1 failed'。Promise.all会立即捕捉到这一拒绝，并返回一个拒绝的Promise。在run函数中，这个拒绝的Promise会被catch块捕捉到，并打印出拒绝的原因。注意，即使asyncOperation2在100毫秒后会解决，Promise.all也不会等待它，因为asyncOperation1已经拒绝了。

其他异步知识可参考：https://blog.csdn.net/cFarmerReally/article/details/79935077
